Traceback (most recent call last):
  File "/opt/hostedtoolcache/Python/3.7.15/x64/lib/python3.7/site-packages/jupyter_cache/executors/utils.py", line 56, in single_nb_execution
    record_timing=False,
  File "/opt/hostedtoolcache/Python/3.7.15/x64/lib/python3.7/site-packages/nbclient/client.py", line 1204, in execute
    return NotebookClient(nb=nb, resources=resources, km=km, **kwargs).execute()
  File "/opt/hostedtoolcache/Python/3.7.15/x64/lib/python3.7/site-packages/nbclient/util.py", line 84, in wrapped
    return just_run(coro(*args, **kwargs))
  File "/opt/hostedtoolcache/Python/3.7.15/x64/lib/python3.7/site-packages/nbclient/util.py", line 62, in just_run
    return loop.run_until_complete(coro)
  File "/opt/hostedtoolcache/Python/3.7.15/x64/lib/python3.7/asyncio/base_events.py", line 587, in run_until_complete
    return future.result()
  File "/opt/hostedtoolcache/Python/3.7.15/x64/lib/python3.7/site-packages/nbclient/client.py", line 664, in async_execute
    cell, index, execution_count=self.code_cells_executed + 1
  File "/opt/hostedtoolcache/Python/3.7.15/x64/lib/python3.7/site-packages/nbclient/client.py", line 965, in async_execute_cell
    await self._check_raise_for_error(cell, cell_index, exec_reply)
  File "/opt/hostedtoolcache/Python/3.7.15/x64/lib/python3.7/site-packages/nbclient/client.py", line 862, in _check_raise_for_error
    raise CellExecutionError.from_cell_and_msg(cell, exec_reply_content)
nbclient.exceptions.CellExecutionError: An error occurred while executing the following cell:
------------------
## Getting a list of available datasets
print("Available datasets through compiam are: {}".format(compiam.list_datasets()))

## Initializing dataloader for an example dataset
fw_tabla_dataset = load_dataset("four_way_tabla")
fw_tabla_dataset
------------------

[0;31m---------------------------------------------------------------------------[0m
[0;31mValueError[0m                                Traceback (most recent call last)
[0;32m/tmp/ipykernel_3000/2337061529.py[0m in [0;36m<module>[0;34m[0m
[1;32m      3[0m [0;34m[0m[0m
[1;32m      4[0m [0;31m## Initializing dataloader for an example dataset[0m[0;34m[0m[0;34m[0m[0;34m[0m[0m
[0;32m----> 5[0;31m [0mfw_tabla_dataset[0m [0;34m=[0m [0mload_dataset[0m[0;34m([0m[0;34m"four_way_tabla"[0m[0;34m)[0m[0;34m[0m[0;34m[0m[0m
[0m[1;32m      6[0m [0mfw_tabla_dataset[0m[0;34m[0m[0;34m[0m[0m

[0;32m/opt/hostedtoolcache/Python/3.7.15/x64/lib/python3.7/site-packages/compiam/__init__.py[0m in [0;36mload_dataset[0;34m(dataset_name, data_home, version)[0m
[1;32m     41[0m     """
[1;32m     42[0m     [0;32mif[0m [0mdataset_name[0m [0;32mnot[0m [0;32min[0m [0mdatasets_list[0m[0;34m:[0m[0;34m[0m[0;34m[0m[0m
[0;32m---> 43[0;31m         [0;32mraise[0m [0mValueError[0m[0;34m([0m[0;34m"Invalid dataset {}"[0m[0;34m.[0m[0mformat[0m[0;34m([0m[0mdataset_name[0m[0;34m)[0m[0;34m)[0m[0;34m[0m[0;34m[0m[0m
[0m[1;32m     44[0m     return mirdata.initialize(
[1;32m     45[0m         [0mdataset_name[0m[0;34m=[0m[0mdataset_name[0m[0;34m,[0m [0mdata_home[0m[0;34m=[0m[0mdata_home[0m[0;34m,[0m [0mversion[0m[0;34m=[0m[0mversion[0m[0;34m[0m[0;34m[0m[0m

[0;31mValueError[0m: Invalid dataset four_way_tabla
ValueError: Invalid dataset four_way_tabla

